<?xml version="1.0" ?>
<!-- =================================================================================== -->
<!-- |    This document was autogenerated by xacro from urdf/phantomx.xacro            | -->
<!-- |    EDITING THIS FILE BY HAND IS NOT RECOMMENDED                                 | -->
<!-- =================================================================================== -->
<robot name="PhantomX" xmlns:xacro="http://www.ros.org/wiki/xacro">
  <link name="base_link"/>
  <joint name="j_phantomx_attachment" type="fixed">
    <parent link="base_link"/>
    <child link="MP_BODY"/>
    <origin rpy="0 0 0" xyz="0 0 0"/>
  </joint>
  <link name="MP_BODY">
    <inertial>
      <origin xyz="0 0 0"/>
      <mass value="0.97559947"/>
      <inertia ixx="3.1081800" ixy="-0.25460189" ixz="2.0318174" iyy="6.3787776" iyz="0.16417863" izz="5.3316425"/>
    </inertial>
    <visual>
      <!--origin xyz="-0.0235 0 -0.03525" rpy="0 0 0" /-->
      <origin rpy="0 0 0" xyz="0 0 0"/>
      <geometry>
        <!--box size="0.102 0.109 0.106" /-->
        <mesh filename="../meshes/body.STL" scale="1 1 1"/>
      </geometry>
      <material name="Grey">
        <color rgba="0.20 0.20 0.20 1.0"/>
      </material>
    </visual>
    <collision>
      <origin rpy="0 0 0" xyz="0 0 0"/>
      <geometry>
        <mesh filename="../meshes/collision/body_coll.obj" scale="1 1 1"/>
      </geometry>
    </collision>
  </link>
  <gazebo reference="MP_BODY">
    <material>Gazebo/Grey</material>
  </gazebo>
  <link name="c1_rf">
    <inertial>
      <origin rpy="0 0 0" xyz="0 -0.02633 0"/>
      <mass value="0.024357719"/>
        <inertia ixx="0.0071411124" ixy="-0.00056530255" ixz="-0.000024729049" iyy="0.0081915737" iyz="-0.000019223094" izz="0.0018379812"/>

    </inertial>
    <visual>
      <origin rpy="0 0 0" xyz="0 -0.0252 0"/>
      <geometry>
        <!--box size="0.045 0.022 0.0325" /-->
        <mesh filename="../meshes/connect.STL" scale="1 1 1"/>
      </geometry>
      <material name="Grey">
        <color rgba="0.20 0.20 0.20 1.0"/>
      </material>
    </visual>
    <collision>
      <origin rpy="0 0 0" xyz="0 -0.02633 0"/>
      <geometry>
        <mesh filename="../meshes/collision/connect_coll.obj" scale="1 1 1"/>
      </geometry>
    </collision>
  </link>
 
  <joint name="j_c1_rf" type="revolute">
    <parent link="MP_BODY"/>
    <child link="c1_rf"/>
    <origin rpy="0 4.7123 0.7853981633974483" xyz="0.1248 -0.06164  0.001116"/>
    <axis xyz="1 0 0"/>
    <limit effort="2.8" lower="-2.6179939" upper="2.6179939" velocity="5.6548668"/>
  </joint>
 
</robot>